Workbook

Sheet 総合評価
A1: 総合 | B1: 配点 | C1: 正答数 | D1: 正答率 | E1: スコア | F1: 評価 | G1: コメント
A2: 総合 | B2: =SUM(Story!D2:D83)+SUM(Bug!D2:D83)+SUM(Task!D2:D83)+SUM('横断品質'!D2:D83) -> 278 | C2: =SUM(Story!F2:F83)+SUM(Bug!F2:F83)+SUM(Task!F2:F83)+SUM('横断品質'!F2:F83) -> 185 | D2: =IFERROR(C2/B2,0) -> 0.66546763 | E2: =5*D2 -> 3.3273381 | F2: =IFS(D2>=0.95,"S",D2>=0.85,"A",D2>=0.7,"B",D2>=0.5,"C",TRUE,"D") -> C | G2: 複数の機能グループで基本的な実装が確認できました。特に質問掲示板、面談パック・プラン管理、お知らせ配信、Stripe連携、Sanctum認証などで部分的な加点が得られています。一方、権限検証・状態遷移の制御、フラッシュメッセージの正確性、バリデーション・エラーハンドリング、Google Calendar・Gemini AI・修了証PDFなどの外部連携機能、およびコード品質が要件と一致していません。
A4: 評価ライン（COACHTECH 標準: S 95 / A 85 / B 70 / C 50） | B4: 閾値 | C4: 必要点 | D4: 到達条件
A5: S | B5: 95 点以上 | C5: =CEILING($B$2*0.95,1) -> 265 | D5: Basic 満点（172 点）+ Advance 93 点（Advance 配点の 87.7%）→ Basic・Advance ともほぼ完答が必要
A6: A | B6: 85 点以上 | C6: =CEILING($B$2*0.85,1) -> 237 | D6: Basic 満点（172 点）+ Advance 65 点（Advance 配点の 61.3%）
A7: B | B7: 70 点以上 | C7: =CEILING($B$2*0.7,1) -> 195 | D7: Basic 満点（172 点）+ Advance 23 点（Advance 配点の 21.7%）
A8: C | B8: 50 点以上 | C8: =CEILING($B$2*0.5,1) -> 139 | D8: Basic のみで到達可（Basic 配点の 80.8%）
A9: D | B9: 50 点未満 | C9: —
A11: 大項目別 | B11: 配点 | C11: 正答数 | D11: 正答率 | E11: スコア | F11: 評価 | G11: コメント
A12: チケット要件 | B12: =SUM(Story!D2:D83)+SUM(Bug!D2:D83)+SUM(Task!D2:D83) -> 221 | C12: =SUM(Story!F2:F83)+SUM(Bug!F2:F83)+SUM(Task!F2:F83) -> 152 | D12: =IFERROR(C12/B12,0) -> 0.68778281 | E12: =5*D12 -> 3.438914 | F12: =IFS(D12>=0.95,"S",D12>=0.85,"A",D12>=0.7,"B",D12>=0.5,"C",TRUE,"D") -> C | G12: チケット要件は 221 点中 152 点でした。要件との差があったのは S-A-01 Google Calendar 連携（面談予約）（12 点）・S-B-01 質問掲示板（7 点）・S-B-05 個人学習目標の管理（7 点）・S-B-07 受講生メモの管理（コーチ）（7 点）・S-B-04 通知基盤（アプリ内＋メール）（6 点）・S-A-02 Gemini AI チャットボット（5 点）・S-B-03 プランのマスタ管理（5 点）・S-A-04 修了証 PDF 出力（4 点）・S-B-02 面談パックのマスタ管理（4 点）・S-A-03 Stripe 連携（追加面談購入）（3 点）・S-B-06 設定・プロフィール（3 点）・S-A-05 Sanctum Cookie 認証 + JS フロント通知表示（2 点）・S-B-08 お知らせ配信（管理者）（2 点）・T-A-04 外部 API 連携のモックテスト追加（2 点）です。詳しくは下のチケット別コメントをご確認ください。
A13: 横断品質 | B13: =SUM('横断品質'!D2:D83) -> 57 | C13: =SUM('横断品質'!F2:F83) -> 33 | D13: =IFERROR(C13/B13,0) -> 0.57894737 | E13: =5*D13 -> 2.8947368 | F13: =IFS(D13>=0.95,"S",D13>=0.85,"A",D13>=0.7,"B",D13>=0.5,"C",TRUE,"D") -> C | G13: 横断品質は 57 点中 33 点でした。要件との差があったのは コード品質（24 点）です。詳しくは下のチケット別コメントをご確認ください。
A15: 種別・難易度別 | B15: 配点 | C15: 正答数 | D15: 正答率 | E15: スコア | F15: 評価 | G15: コメント
A16: Story（Basic） | B16: =SUMIF(Story!$B$2:$B83,"S-B-*",Story!$D$2:$D83) -> 82 | C16: =SUMIF(Story!$B$2:$B83,"S-B-*",Story!$F$2:$F83) -> 41 | D16: =IFERROR(C16/B16,0) -> 0.5 | E16: =5*D16 -> 2.5 | F16: =IFS(D16>=0.95,"S",D16>=0.85,"A",D16>=0.7,"B",D16>=0.5,"C",TRUE,"D") -> C | G16: Story（Basic）は 82 点中 41 点でした。要件との差があったのは S-B-01 質問掲示板（7 点）・S-B-05 個人学習目標の管理（7 点）・S-B-07 受講生メモの管理（コーチ）（7 点）・S-B-04 通知基盤（アプリ内＋メール）（6 点）・S-B-03 プランのマスタ管理（5 点）・S-B-02 面談パックのマスタ管理（4 点）・S-B-06 設定・プロフィール（3 点）・S-B-08 お知らせ配信（管理者）（2 点）です。詳しくは下のチケット別コメントをご確認ください。
A17: Story（Advance） | B17: =SUMIF(Story!$B$2:$B83,"S-A-*",Story!$D$2:$D83) -> 64 | C17: =SUMIF(Story!$B$2:$B83,"S-A-*",Story!$F$2:$F83) -> 38 | D17: =IFERROR(C17/B17,0) -> 0.59375 | E17: =5*D17 -> 2.96875 | F17: =IFS(D17>=0.95,"S",D17>=0.85,"A",D17>=0.7,"B",D17>=0.5,"C",TRUE,"D") -> C | G17: Story（Advance）は 64 点中 38 点でした。要件との差があったのは S-A-01 Google Calendar 連携（面談予約）（12 点）・S-A-02 Gemini AI チャットボット（5 点）・S-A-04 修了証 PDF 出力（4 点）・S-A-03 Stripe 連携（追加面談購入）（3 点）・S-A-05 Sanctum Cookie 認証 + JS フロント通知表示（2 点）です。詳しくは下のチケット別コメントをご確認ください。
A18: Bug（Basic） | B18: =SUMIF(Bug!$B$2:$B83,"B-B-*",Bug!$D$2:$D83) -> 43 | C18: =SUMIF(Bug!$B$2:$B83,"B-B-*",Bug!$F$2:$F83) -> 43 | D18: =IFERROR(C18/B18,0) -> 1 | E18: =5*D18 -> 5 | F18: =IFS(D18>=0.95,"S",D18>=0.85,"A",D18>=0.7,"B",D18>=0.5,"C",TRUE,"D") -> S | G18: Bug（Basic）は 43 点中 43 点、全 33 項目が加点となりました。
A19: Bug（Advance） | B19: =SUMIF(Bug!$B$2:$B83,"B-A-*",Bug!$D$2:$D83) -> 10 | C19: =SUMIF(Bug!$B$2:$B83,"B-A-*",Bug!$F$2:$F83) -> 10 | D19: =IFERROR(C19/B19,0) -> 1 | E19: =5*D19 -> 5 | F19: =IFS(D19>=0.95,"S",D19>=0.85,"A",D19>=0.7,"B",D19>=0.5,"C",TRUE,"D") -> S | G19: Bug（Advance）は 10 点中 10 点、全 6 項目が加点となりました。
A20: Task（Basic） | B20: =SUMIF(Task!$B$2:$B83,"T-B-*",Task!$D$2:$D83) -> 4 | C20: =SUMIF(Task!$B$2:$B83,"T-B-*",Task!$F$2:$F83) -> 4 | D20: =IFERROR(C20/B20,0) -> 1 | E20: =5*D20 -> 5 | F20: =IFS(D20>=0.95,"S",D20>=0.85,"A",D20>=0.7,"B",D20>=0.5,"C",TRUE,"D") -> S | G20: Task（Basic）は 4 点中 4 点、全 2 項目が加点となりました。
A21: Task（Advance） | B21: =SUMIF(Task!$B$2:$B83,"T-A-*",Task!$D$2:$D83) -> 18 | C21: =SUMIF(Task!$B$2:$B83,"T-A-*",Task!$F$2:$F83) -> 16 | D21: =IFERROR(C21/B21,0) -> 0.88888889 | E21: =5*D21 -> 4.4444444 | F21: =IFS(D21>=0.95,"S",D21>=0.85,"A",D21>=0.7,"B",D21>=0.5,"C",TRUE,"D") -> A | G21: Task（Advance）は 18 点中 16 点でした。要件との差があったのは T-A-04 外部 API 連携のモックテスト追加（2 点）です。詳しくは下のチケット別コメントをご確認ください。
A22: 横断品質（Basic） | B22: =SUM('横断品質'!D2:D83)-SUMIF('横断品質'!$C$2:$C83,"（応用）*",'横断品質'!$D$2:$D83) -> 43 | C22: =SUM('横断品質'!F2:F83)-SUMIF('横断品質'!$C$2:$C83,"（応用）*",'横断品質'!$F$2:$F83) -> 24 | D22: =IFERROR(C22/B22,0) -> 0.55813953 | E22: =5*D22 -> 2.7906977 | F22: =IFS(D22>=0.95,"S",D22>=0.85,"A",D22>=0.7,"B",D22>=0.5,"C",TRUE,"D") -> C | G22: 横断品質（Basic）は 43 点中 24 点でした。要件との差があったのは コード品質（19 点）です。詳しくは下のチケット別コメントをご確認ください。
A23: 横断品質（応用） | B23: =SUMIF('横断品質'!$C$2:$C83,"（応用）*",'横断品質'!$D$2:$D83) -> 14 | C23: =SUMIF('横断品質'!$C$2:$C83,"（応用）*",'横断品質'!$F$2:$F83) -> 9 | D23: =IFERROR(C23/B23,0) -> 0.64285714 | E23: =5*D23 -> 3.2142857 | F23: =IFS(D23>=0.95,"S",D23>=0.85,"A",D23>=0.7,"B",D23>=0.5,"C",TRUE,"D") -> C | G23: 横断品質（応用）は 14 点中 9 点でした。要件との差があったのは コード品質（5 点）です。詳しくは下のチケット別コメントをご確認ください。
A24: Basic 計 | B24: =B16+B18+B20+B22 -> 172 | C24: =C16+C18+C20+C22 -> 112 | D24: =IFERROR(C24/B24,0) -> 0.65116279 | E24: =5*D24 -> 3.255814 | F24: =IFS(D24>=0.95,"S",D24>=0.85,"A",D24>=0.7,"B",D24>=0.5,"C",TRUE,"D") -> C | G24: Basic 計は 172 点中 112 点でした。要件との差があったのは コード品質（19 点）・S-B-01 質問掲示板（7 点）・S-B-05 個人学習目標の管理（7 点）・S-B-07 受講生メモの管理（コーチ）（7 点）・S-B-04 通知基盤（アプリ内＋メール）（6 点）・S-B-03 プランのマスタ管理（5 点）・S-B-02 面談パックのマスタ管理（4 点）・S-B-06 設定・プロフィール（3 点）・S-B-08 お知らせ配信（管理者）（2 点）です。詳しくは下のチケット別コメントをご確認ください。
A25: Advance 計 | B25: =B17+B19+B21+B23 -> 106 | C25: =C17+C19+C21+C23 -> 73 | D25: =IFERROR(C25/B25,0) -> 0.68867925 | E25: =5*D25 -> 3.4433962 | F25: =IFS(D25>=0.95,"S",D25>=0.85,"A",D25>=0.7,"B",D25>=0.5,"C",TRUE,"D") -> C | G25: Advance 計は 106 点中 73 点でした。要件との差があったのは S-A-01 Google Calendar 連携（面談予約）（12 点）・S-A-02 Gemini AI チャットボット（5 点）・コード品質（5 点）・S-A-04 修了証 PDF 出力（4 点）・S-A-03 Stripe 連携（追加面談購入）（3 点）・S-A-05 Sanctum Cookie 認証 + JS フロント通知表示（2 点）・T-A-04 外部 API 連携のモックテスト追加（2 点）です。詳しくは下のチケット別コメントをご確認ください。
A27: チケット別 | B27: 配点 | C27: 正答数 | D27: 正答率 | E27: スコア | F27: 評価 | G27: コメント
A28: S-B-01 質問掲示板 | B28: =SUMIF(Story!$B$2:$B83,$A28,Story!$D$2:$D83) -> 14 | C28: =SUMIF(Story!$B$2:$B83,$A28,Story!$F$2:$F83) -> 7 | D28: =IFERROR(C28/B28,0) -> 0.5 | E28: =5*D28 -> 2.5 | F28: =IFS(D28>=0.95,"S",D28>=0.85,"A",D28>=0.7,"B",D28>=0.5,"C",TRUE,"D") -> C | G28: スレッド投稿・削除・回答機能の基本的な実装が確認できました。一方、回答が付いているスレッドの削除時に成功メッセージが表示される、公開停止資格のスレッドが表示される、コーチが担当外資格のスレッドを閲覧できる、公開されていない資格への投稿が成功と伝えられるなど、権限・状態の検証とフラッシュメッセージの制御が要件と一致していません。
A29: S-B-02 面談パックのマスタ管理 | B29: =SUMIF(Story!$B$2:$B83,$A29,Story!$D$2:$D83) -> 8 | C29: =SUMIF(Story!$B$2:$B83,$A29,Story!$F$2:$F83) -> 4 | D29: =IFERROR(C29/B29,0) -> 0.5 | E29: =5*D29 -> 2.5 | F29: =IFS(D29>=0.95,"S",D29>=0.85,"A",D29>=0.7,"B",D29>=0.5,"C",TRUE,"D") -> C | G29: 一覧表示・ステータス遷移の基本機能が実装されています。新規作成後の遷移先、ステータス遷移後の遷移先、および価格の上限値バリデーションが要件と一致していません。
A30: S-B-03 プランのマスタ管理 | B30: =SUMIF(Story!$B$2:$B83,$A30,Story!$D$2:$D83) -> 9 | C30: =SUMIF(Story!$B$2:$B83,$A30,Story!$F$2:$F83) -> 4 | D30: =IFERROR(C30/B30,0) -> 0.44444444 | E30: =5*D30 -> 2.2222222 | F30: =IFS(D30>=0.95,"S",D30>=0.85,"A",D30>=0.7,"B",D30>=0.5,"C",TRUE,"D") -> D | G30: プラン管理の基本的な機能が実装されています。新規作成後の遷移先、アーカイブ状態のプランの削除制御、ステータス遷移後の遷移先、および期間日数の上限値バリデーションが要件と一致していません。
A31: S-B-04 通知基盤（アプリ内＋メール） | B31: =SUMIF(Story!$B$2:$B83,$A31,Story!$D$2:$D83) -> 10 | C31: =SUMIF(Story!$B$2:$B83,$A31,Story!$F$2:$F83) -> 4 | D31: =IFERROR(C31/B31,0) -> 0.4 | E31: =5*D31 -> 2 | F31: =IFS(D31>=0.95,"S",D31>=0.85,"A",D31>=0.7,"B",D31>=0.5,"C",TRUE,"D") -> D | G31: 通知機能の基本的なルート設計が確認できました。チャットメッセージ投稿時の通知生成、Q&Aスレッド回答時の通知生成、面談予約時の通知生成、面談キャンセル時の通知生成が要件どおりに動作することを確認できませんでした。また、Q&A回答時に投稿者本人が自身に通知を受け取らないようにする制御が要件と一致していません。
A32: S-B-05 個人学習目標の管理 | B32: =SUMIF(Story!$B$2:$B83,$A32,Story!$D$2:$D83) -> 8 | C32: =SUMIF(Story!$B$2:$B83,$A32,Story!$F$2:$F83) -> 1 | D32: =IFERROR(C32/B32,0) -> 0.125 | E32: =5*D32 -> 0.625 | F32: =IFS(D32>=0.95,"S",D32>=0.85,"A",D32>=0.7,"B",D32>=0.5,"C",TRUE,"D") -> D | G32: 目標機能のルート設計が確認できました。目標追加後の遷移、目標編集・削除・達成状態の操作、および目標一覧の表示が要件どおりに動作することを確認できませんでした。また、バリデーション違反時のエラーメッセージが要件と一致していません。
A33: S-B-06 設定・プロフィール | B33: =SUMIF(Story!$B$2:$B83,$A33,Story!$D$2:$D83) -> 8 | C33: =SUMIF(Story!$B$2:$B83,$A33,Story!$F$2:$F83) -> 5 | D33: =IFERROR(C33/B33,0) -> 0.625 | E33: =5*D33 -> 3.125 | F33: =IFS(D33>=0.95,"S",D33>=0.85,"A",D33>=0.7,"B",D33>=0.5,"C",TRUE,"D") -> C | G33: プロフィール更新の基本機能が実装されています。自己紹介の保存、固定面談URLの保存と表示、およびバリデーション違反時の入力値復元が要件と一致していません。
A34: S-B-07 受講生メモの管理（コーチ） | B34: =SUMIF(Story!$B$2:$B83,$A34,Story!$D$2:$D83) -> 8 | C34: =SUMIF(Story!$B$2:$B83,$A34,Story!$F$2:$F83) -> 1 | D34: =IFERROR(C34/B34,0) -> 0.125 | E34: =5*D34 -> 0.625 | F34: =IFS(D34>=0.95,"S",D34>=0.85,"A",D34>=0.7,"B",D34>=0.5,"C",TRUE,"D") -> D | G34: メモ機能のルート設計が確認できました。メモの追加・編集・削除・一覧表示が要件どおりに動作することを確認できませんでした。また、バリデーション違反時の入力値復元が要件と一致していません。
A35: S-B-08 お知らせ配信（管理者） | B35: =SUMIF(Story!$B$2:$B83,$A35,Story!$D$2:$D83) -> 12 | C35: =SUMIF(Story!$B$2:$B83,$A35,Story!$F$2:$F83) -> 10 | D35: =IFERROR(C35/B35,0) -> 0.83333333 | E35: =5*D35 -> 4.1666667 | F35: =IFS(D35>=0.95,"S",D35>=0.85,"A",D35>=0.7,"B",D35>=0.5,"C",TRUE,"D") -> B | G35: お知らせ配信機能の大部分が実装されています。退会済受講生への配信除外、およびタイトル・本文の上限値バリデーションが要件と一致していません。
A36: S-B-09 面談リマインダー通知（前日・1時間前） | B36: =SUMIF(Story!$B$2:$B83,$A36,Story!$D$2:$D83) -> 5 | C36: =SUMIF(Story!$B$2:$B83,$A36,Story!$F$2:$F83) -> 5 | D36: =IFERROR(C36/B36,0) -> 1 | E36: =5*D36 -> 5 | F36: =IFS(D36>=0.95,"S",D36>=0.85,"A",D36>=0.7,"B",D36>=0.5,"C",TRUE,"D") -> S | G36: S-B-09面談リマインダー通知（前日・1時間前）は、全5項目で減点はありませんでした。この調子で他の機能も仕上げていきましょう。
A37: S-A-01 Google Calendar 連携（面談予約） | B37: =SUMIF(Story!$B$2:$B83,$A37,Story!$D$2:$D83) -> 13 | C37: =SUMIF(Story!$B$2:$B83,$A37,Story!$F$2:$F83) -> 1 | D37: =IFERROR(C37/B37,0) -> 0.076923077 | E37: =5*D37 -> 0.38461538 | F37: =IFS(D37>=0.95,"S",D37>=0.85,"A",D37>=0.7,"B",D37>=0.5,"C",TRUE,"D") -> D | G37: 連携完了時のフラッシュメッセージ、解除時のGoogle側のアクセス権失効、空き枠取得時のカレンダー予定反映、Event作成・削除、期限切れトークンの自動更新が要件と一致していません。
A38: S-A-02 Gemini AI チャットボット | B38: =SUMIF(Story!$B$2:$B83,$A38,Story!$D$2:$D83) -> 13 | C38: =SUMIF(Story!$B$2:$B83,$A38,Story!$F$2:$F83) -> 8 | D38: =IFERROR(C38/B38,0) -> 0.61538462 | E38: =5*D38 -> 3.0769231 | F38: =IFS(D38>=0.95,"S",D38>=0.85,"A",D38>=0.7,"B",D38>=0.5,"C",TRUE,"D") -> C | G38: AI相談機能の基本的な実装が確認できました。フル画面での会話作成時のフラッシュメッセージ、機能スイッチOFF時のアクセス制御、APIキー未設定時の送信制御、ウィジェットでの会話ID保持、および初回メッセージの文字数バリデーションが要件と一致していません。
A39: S-A-03 Stripe 連携（追加面談購入） | B39: =SUMIF(Story!$B$2:$B83,$A39,Story!$D$2:$D83) -> 15 | C39: =SUMIF(Story!$B$2:$B83,$A39,Story!$F$2:$F83) -> 12 | D39: =IFERROR(C39/B39,0) -> 0.8 | E39: =5*D39 -> 4 | F39: =IFS(D39>=0.95,"S",D39>=0.85,"A",D39>=0.7,"B",D39>=0.5,"C",TRUE,"D") -> B | G39: Stripe連携の基本的な実装が確認できました。決済完了画面での購入記録の状態表示が要件と一致していません。
A40: S-A-04 修了証 PDF 出力 | B40: =SUMIF(Story!$B$2:$B83,$A40,Story!$D$2:$D83) -> 8 | C40: =SUMIF(Story!$B$2:$B83,$A40,Story!$F$2:$F83) -> 4 | D40: =IFERROR(C40/B40,0) -> 0.5 | E40: =5*D40 -> 2.5 | F40: =IFS(D40>=0.95,"S",D40>=0.85,"A",D40>=0.7,"B",D40>=0.5,"C",TRUE,"D") -> C | G40: 修了証機能のルート設計が確認できました。PDF生成・保管、ダウンロード時のファイル名、および保管領域にファイルが無い場合の制御が要件と一致していません。
A41: S-A-05 Sanctum Cookie 認証 + JS フロント通知表示 | B41: =SUMIF(Story!$B$2:$B83,$A41,Story!$D$2:$D83) -> 15 | C41: =SUMIF(Story!$B$2:$B83,$A41,Story!$F$2:$F83) -> 13 | D41: =IFERROR(C41/B41,0) -> 0.86666667 | E41: =5*D41 -> 4.3333333 | F41: =IFS(D41>=0.95,"S",D41>=0.85,"A",D41>=0.7,"B",D41>=0.5,"C",TRUE,"D") -> A | G41: 認証・通知表示機能の大部分が実装されています。一覧APIの通知種別フィールドと、管理者で通知が0件のときの空状態の表示が要件と一致していません。
A42: B-B-01 コーチが担当資格の教材管理にアクセスすると 403 | B42: =SUMIF(Bug!$B$2:$B83,$A42,Bug!$D$2:$D83) -> 2 | C42: =SUMIF(Bug!$B$2:$B83,$A42,Bug!$F$2:$F83) -> 2 | D42: =IFERROR(C42/B42,0) -> 1 | E42: =5*D42 -> 5 | F42: =IFS(D42>=0.95,"S",D42>=0.85,"A",D42>=0.7,"B",D42>=0.5,"C",TRUE,"D") -> S | G42: B-B-01コーチが担当資格の教材管理にアクセスすると403は全2項目が加点となりました。要件を一つひとつ確認しながら進められたことが伝わってきます。
A43: B-B-02 教材管理の階層一覧が並び順を無視して表示される | B43: =SUMIF(Bug!$B$2:$B83,$A43,Bug!$D$2:$D83) -> 2 | C43: =SUMIF(Bug!$B$2:$B83,$A43,Bug!$F$2:$F83) -> 2 | D43: =IFERROR(C43/B43,0) -> 1 | E43: =5*D43 -> 5 | F43: =IFS(D43>=0.95,"S",D43>=0.85,"A",D43>=0.7,"B",D43>=0.5,"C",TRUE,"D") -> S | G43: B-B-02教材管理の階層一覧が並び順を無視して表示されるは、全2項目で減点はありませんでした。この調子で他の機能も仕上げていきましょう。
A44: B-B-03 公開停止した資格の教材が受講生に閲覧できてしまう | B44: =SUMIF(Bug!$B$2:$B83,$A44,Bug!$D$2:$D83) -> 2 | C44: =SUMIF(Bug!$B$2:$B83,$A44,Bug!$F$2:$F83) -> 2 | D44: =IFERROR(C44/B44,0) -> 1 | E44: =5*D44 -> 5 | F44: =IFS(D44>=0.95,"S",D44>=0.85,"A",D44>=0.7,"B",D44>=0.5,"C",TRUE,"D") -> S | G44: B-B-03公開停止した資格の教材が受講生に閲覧できてしまうは、全2項目で減点はありませんでした。この調子で他の機能も仕上げていきましょう。
...

Sheet Story
A1: 大項目 | B1: 中項目 | C1: 評価基準 | D1: 評価点 | E1: 可否 | F1: 点数
A2: チケット要件 | B2: S-B-01 質問掲示板 | C2: 【受講生】 1. /qa-board/create から資格選択 + タイトル + 本文を入力してスレッドを投稿できる 2. 成功時に作成されたスレッド詳細(/qa-board/{thread})へリダイレクトする 3. フラッシュメッセージ「質問を投稿しました。」が表示される | D2: 1 | E2: TRUE | F2: =IF(E2,D2,0) -> 1
A3: チケット要件 | B3: S-B-01 質問掲示板 | C3: 【受講生】 1. 投稿者本人がタイトル・本文を編集できる(資格は変更不可) 2. 投稿者以外はアクセスできない 3. 成功時にスレッド詳細へリダイレクトし、フラッシュメッセージ「質問を更新しました。」が表示される | D3: 1 | E3: TRUE | F3: =IF(E3,D3,0) -> 1
A4: チケット要件 | B4: S-B-01 質問掲示板 | C4: 【受講生】 1. 投稿者本人は回答 0 件のスレッドのみ削除でき、成功時にフラッシュメッセージ「質問を削除しました。」が表示される 2. 回答有りのスレッドは削除できず、フラッシュエラー「回答が付いているスレッドは削除できません。」が表示される | D4: 1 | E4: FALSE | F4: =IF(E4,D4,0) -> 0
A5: チケット要件 | B5: S-B-01 質問掲示板 | C5: 【受講生】 1. 投稿者本人のスレッド詳細にのみ解決マーク / 解除ボタンが表示される(本人以外には表示されない) 2. マークすると解決済みバッジと解決日時が表示される(フラッシュ「質問を解決済にマークしました。」) 3. 解除すると未解決表示に戻り解決日時の表示も消える(フラッシュ「質問を未解決に戻しました。」) | D5: 2 | E5: TRUE | F5: =IF(E5,D5,0) -> 2
A6: チケット要件 | B6: S-B-01 質問掲示板 | C6: 【受講生・コーチ】 1. 受講生 / コーチが回答を投稿・編集・自削除できる 2. 編集はインライン編集ではなく回答編集フォームに遷移して行う 3. 各操作の成功時にフラッシュ表示(「回答を投稿しました。」「回答を更新しました。」「回答を削除しました。」) | D6: 1 | E6: TRUE | F6: =IF(E6,D6,0) -> 1
A7: チケット要件 | B7: S-B-01 質問掲示板 | C7: 【受講生・コーチ】 1. 受講生は公開済資格すべて、コーチは担当資格のみのスレッドを一覧で見られる 2. 資格別 / 解決状態 / キーワード(タイトル / 本文 / 回答本文の OR 部分一致)で絞り込みできる 3. 質問スレッド作成(回答順ではない)の新着順 20 件 / ページのページネーションが実装されている | D7: 2 | E7: FALSE | F7: =IF(E7,D7,0) -> 0
A8: チケット要件 | B8: S-B-01 質問掲示板 | C8: 【受講生・コーチ】 1. スレッド詳細画面で配下回答が古い順(投稿順)で全件表示される(回答ページネーションなし) | D8: 1 | E8: TRUE | F8: =IF(E8,D8,0) -> 1
A9: チケット要件 | B9: S-B-01 質問掲示板 | C9: 【管理者】 1. /admin/qa-board 経由で全資格(公開停止資格含む)のスレッドを横断閲覧できる 2. 任意のスレッド / 回答を無条件で削除できる(スレッド削除時に配下回答も連動削除、フラッシュ「質問を削除しました。」) 3. 管理者の画面にはスレッド投稿 / 編集 / 解決マークの操作ボタンは表示されない(モデレーションは削除のみ) | D9: 1 | E9: FALSE | F9: =IF(E9,D9,0) -> 0
A10: チケット要件 | B10: S-B-01 質問掲示板 | C10: 【コーチ・受講生】 1. コーチは担当外資格のスレッドを直接 URL 指定 or 一覧クエリで指定しても閲覧できない(資格存在は隠蔽しない) 2. 受講生・コーチは公開停止資格のスレッドを閲覧できない(資格自体が見えない扱い、管理者は引き続き閲覧可) | D10: 2 | E10: FALSE | F10: =IF(E10,D10,0) -> 0
A11: チケット要件 | B11: S-B-01 質問掲示板 | C11: 【受講生・コーチ】 1. スレッド投稿 / 編集 / 回答投稿 / 回答編集フォームで違反時に日本語エラーが表示される a. 資格 = 必須(公開済資格のみ) b. タイトル = 必須・200 文字以内・全角通常空白のみ不可 c. 本文〈スレッド / 回答〉 = 必須・5000 文字以内・全角通常空白のみ不可 (メッセージ例: 「資格を選択してください。」「タイトルを入力してください。」「タイトルは 200 文字以内で入力してください。」「本文を入力してください。」「本文は 5000 文字以内で入力してください。」) ※文字数上限は blade の maxlength で入力段階から担保(超過入力不可のため超過時のエラー表示の確認は不要) | D11: 1 | E11: FALSE | F11: =IF(E11,D11,0) -> 0
A12: チケット要件 | B12: S-B-01 質問掲示板 | C12: 本チケットの機能に対するテスト（Unit / Feature 等）が実装されている | D12: 1 | E12: TRUE | F12: =IF(E12,D12,0) -> 1
A13: チケット要件 | B13: S-B-02 面談パックのマスタ管理 | C13: 【管理者】 1. 面談パック管理画面で一覧を閲覧できる 2. パック名キーワード(部分一致)+ ステータス(下書き / 公開中 / アーカイブ)フィルタで絞り込める 3. 公開中を優先する並び順で表示される | D13: 1 | E13: FALSE | F13: =IF(E13,D13,0) -> 0
... A128: チケット要件 | B128: S-A-05 Sanctum Cookie 認証 + JS フロント通知表示 | C128: 本チケットの機能に対するテスト（Unit / Feature 等）が実装されている | D128: 1 | E128: TRUE | F128: =IF(E128,D128,0) -> 1

Sheet Bug
A1: 大項目 | B1: 中項目 | C1: 評価基準 | D1: 評価点 | E1: 可否 | F1: 点数
A2: チケット要件 | B2: B-B-01 コーチが担当資格の教材管理にアクセスすると 403 | C2: 【コーチ】 1. 担当資格を持つコーチが当該資格の資格管理マスタ画面の詳細（Part / Chapter / Section / 演習問題 / 出題分野マスタ）を正常に開ける 2. 作成・編集・削除・公開非公開・画像アップロードが認可で弾かれず実行できる | D2: 1 | E2: TRUE | F2: =IF(E2,D2,0) -> 1
A3: チケット要件 | B3: B-B-01 コーチが担当資格の教材管理にアクセスすると 403 | C3: 同梱 tests/Unit/Policies/PartPolicyTest.php::test_coach_assigned_only（修正前は赤）が pass する | D3: 1 | E3: TRUE | F3: =IF(E3,D3,0) -> 1
A4: チケット要件 | B4: B-B-02 教材管理の階層一覧が並び順を無視して表示される | C4: 【管理者・コーチ】 1. 資格管理マスタの各階層一覧（Part 一覧 / Part 詳細の Chapter 一覧 / Chapter 詳細の Section 一覧）が、いずれも並び順（order 昇順）で表示される | D4: 1 | E4: TRUE | F4: =IF(E4,D4,0) -> 1
A5: チケット要件 | B5: B-B-02 教材管理の階層一覧が並び順を無視して表示される | C5: 同梱の並び順テスト（修正前は赤）が pass する 確認方法（テスト）: tests/Feature/Http/Part/IndexTest.php::test_parts_are_listed_in_order_ascending / Part/ShowTest.php::test_chapters_are_listed_in_order_ascending / Chapter/ShowTest.php::test_sections_are_listed_in_order_ascending | D5: 1 | E5: TRUE | F5: =IF(E5,D5,0) -> 1
A6: チケット要件 | B6: B-B-03 公開停止した資格の教材が受講生に閲覧できてしまう | C6: 【受講生】 1. 受講登録済みの受講生は公開中でない（アーカイブ / 下書き）資格の教材詳細（Part / Chapter / Section）を閲覧できない | D6: 1 | E6: TRUE | F6: =IF(E6,D6,0) -> 1
A7: チケット要件 | B7: B-B-03 公開停止した資格の教材が受講生に閲覧できてしまう | C7: 同梱 tests/Feature/Http/Learning/BrowseControllerTest.php::test_show_part_404_when_certification_archived（修正前は赤）が pass する | D7: 1 | E7: TRUE | F7: =IF(E7,D7,0) -> 1
A8: チケット要件 | B8: B-B-04 管理者の受講生一覧に退会済みユーザーが表示される | C8: 【管理者】 1. ユーザー管理画面で状態フィルタなし、および在籍系（受講中 / 卒業）で絞り込んだとき退会済みユーザーが一覧に表示されない 2. ユーザー管理画面で状態フィルタを「退会済」にしたときのみ退会済みユーザーが表示される | D8: 2 | E8: TRUE | F8: =IF(E8,D8,0) -> 2
A9: チケット要件 | B9: B-B-04 管理者の受講生一覧に退会済みユーザーが表示される | C9: 同梱 tests/Feature/Http/User/IndexTest.php::test_status_filter_excludes_withdrawn_by_default（修正前は赤）が pass する | D9: 1 | E9: TRUE | F9: =IF(E9,D9,0) -> 1
A10: チケット要件 | B10: B-B-05 模試の合格点を 100% 超に設定でき誰も合格できなくなる | C10: 【管理者】 1. 模試マスタの作成・編集で合格点に 100 を超える値を入力すると日本語のバリデーションエラーが表示され保存されない（設定できるのは 1〜100 のみ） 2. 参考: 「合格点(%) は 1 から 100 の間で指定してください。」 | D10: 1 | E10: TRUE | F10: =IF(E10,D10,0) -> 1
A11: チケット要件 | B11: B-B-05 模試の合格点を 100% 超に設定でき誰も合格できなくなる | C11: 【受講生】 1. 模試受験履歴から結果画面にアクセスすると、合格点が適切な模試では得点率が合格点以上で合格・未満で不合格と判定される | D11: 1 | E11: TRUE | F11: =IF(E11,D11,0) -> 1
A12: チケット要件 | B12: B-B-05 模試の合格点を 100% 超に設定でき誰も合格できなくなる | C12: 同梱 tests/Unit/Http/Requests/MockExam/StoreRequestTest.php::test_validation_fails（passing_score 101、修正前は赤）が pass する | D12: 1 | E12: TRUE | F12: =IF(E12,D12,0) -> 1
A13: チケット要件 | B13: B-B-06 招待トークンが使い回せてしまう | C13: 【受講生】 1. オンボーディングを完了した招待 URL に再アクセスすると、招待リンクが無効である案内画面が表示される 2. オンボーディングを再実行できない | D13: 2 | E13: TRUE | F13: =IF(E13,D13,0) -> 2
... A40: チケット要件 | B40: B-A-03 模試をキャンセルしても学習タームが基礎タームに戻らない | C40: 同梱 tests/Unit/Services/TermJudgementServiceTest.php::test_returns_basic_learning_when_only_canceled_session_exists（修正前は赤）が pass する | D40: 1 | E40: TRUE | F40: =IF(E40,D40,0) -> 1

Sheet Task
A1: 大項目 | B1: 中項目 | C1: 評価基準 | D1: 評価点 | E1: 可否 | F1: 点数
A2: チケット要件 | B2: T-B-01 コーチダッシュボードの担当受講生一覧の N+1 解消 | C2: コーチダッシュボードの担当受講生一覧で受講生情報・担当資格・最終活動日時が一括取得され N+1 が解消されている 確認方法（テスト）: 同梱の tests/Feature/Http/Dashboard/DashboardQueryCountTest.php::test_coach_dashboard_does_not_explode_with_more_enrollments（修正前は失敗）が pass する（担当受講生を増やしても発行クエリ数が増えないことを検証） | D2: 2 | E2: TRUE | F2: =IF(E2,D2,0) -> 2
A3: チケット要件 | B3: T-B-02 大量レコードを扱う定期実行処理のメモリ最適化（chunk 処理） | C3: 対象 3 件の定期実行コマンドが、1 回の読み込み件数を超える件数（例: 数百件）を投入してもコマンドが完走し、処理中に絞り込み条件となる状態を更新しても取りこぼしが起きず、対象全件が期待どおり状態遷移する 確認方法（テスト）: 同梱の tests/Feature/Commands/ScheduleCommandChunkTest.php（対象 3 コマンドの全件処理を検証、修正前は失敗）が pass する | D3: 2 | E3: TRUE | F3: =IF(E3,D3,0) -> 2
A4: チケット要件 | B4: T-A-01 模試マスタ一覧の N+1 解消 | C4: 模試マスタ一覧で、模試の件数が増えても発行クエリ数が増えない（所属資格 / 作成者 / 更新者 / 問題数が一括取得される） 確認方法（テスト）: 同梱の tests/Feature/Http/MockExam/MockExamIndexQueryCountTest.php::test_index_query_count_does_not_grow_with_mock_exam_count（修正前は失敗）が pass する | D4: 2 | E4: TRUE | F4: =IF(E4,D4,0) -> 2
A5: チケット要件 | B5: T-A-02 面談機能のロジックを Action へ分離 | C5: MeetingController の受講生予約 / 当事者キャンセル / コーチメモ upsert の状態変更 3 操作の業務ロジックが単一責務 Action（例: Meeting\StoreAction / CancelAction / UpsertMemoAction）に切り出され、各 Controller メソッドが Action 呼出 + 認可委譲 + レスポンス整形のみの薄いラッパー（業務ロジックの if / 計算 0 行）になっている | D5: 2 | E5: TRUE | F5: =IF(E5,D5,0) -> 2
A6: チケット要件 | B6: T-A-02 面談機能のロジックを Action へ分離 | C6: MeetingController の受講生向け一覧 / コーチ向け一覧 / 面談詳細 / 空き枠取得の取得系 4 メソッドのデータ取得処理が対応する Action（例: Meeting\IndexAction / IndexAsCoachAction / ShowAction / FetchAvailabilityAction）に切り出され、各 Controller メソッドがクエリ組み立てを持たず Action 呼出 + レスポンス整形のみになっている（予約フォーム表示の create / createFallback は対象外） | D6: 1 | E6: TRUE | F6: =IF(E6,D6,0) -> 1
A7: チケット要件 | B7: T-A-02 面談機能のロジックを Action へ分離 | C7: 状態変更を伴う Action がトランザクション境界で全副作用を囲み、整合性違反（残面談回数 0 / 枠外 / 候補コーチ 0 名 / 状態遷移不可 / 開始時刻超過 等）を Action 内で面談ドメインの専用例外（例: app/Exceptions/Mentoring/* + InsufficientMeetingQuotaException。クラス名・配置は例で、完全一致は不要）で throw してロールバックする | D7: 1 | E7: TRUE | F7: =IF(E7,D7,0) -> 1
A8: チケット要件 | B8: T-A-02 面談機能のロジックを Action へ分離 | C8: 本チケットの機能に対するテスト（Unit / Feature 等）が実装されている（状態変更系 Action の単体テスト + 取得系の振る舞いテストを含む。模範解答: StoreActionTest / CancelActionTest / UpsertMemoActionTest + MeetingControllerTest） | D8: 1 | E8: TRUE | F8: =IF(E8,D8,0) -> 1
A9: チケット要件 | B9: T-A-03 学習進捗の集計ロジックを Service へ集約 | C9: 学習進捗の集計処理（EnrollmentController::show / ShowEnrollmentAction / FetchStudentDashboardAction で利用）が専用 Service（例: ProgressService）に集約されており、各 Controller / Action 側に進捗集計の重複ロジックが残っていない | D9: 2 | E9: TRUE | F9: =IF(E9,D9,0) -> 2
A10: チケット要件 | B10: T-A-03 学習進捗の集計ロジックを Service へ集約 | C10: 本チケットの機能に対するテスト（Unit / Feature 等）が実装されている（集約した Service の単体テストを含む。模範解答: ProgressServiceTest） | D10: 1 | E10: TRUE | F10: =IF(E10,D10,0) -> 1
A11: チケット要件 | B11: T-A-04 外部 API 連携のモックテスト追加 | C11: 3 つの外部 API 連携（Google Calendar / Gemini AI / Stripe Webhook）それぞれに外部 API へ実接続しないモックテストが追加され、正常系に加えて異常系・境界系（HTTP エラー / 一時エラーからのリトライ / トークン期限切れ・リフレッシュ / 空応答 / 署名の有効・無効・欠落 / 二重配信の冪等性 等）を検証している | D11: 2 | E11: TRUE | F11: =IF(E11,D11,0) -> 2
A12: チケット要件 | B12: T-A-04 外部 API 連携のモックテスト追加 | C12: 利用側（面談予約 / キャンセル / 空き枠集計 / 連携設定）のテストが外部ライブラリの低レベル呼出ではなく外部連携のまとまり単位でスタブ化されている | D12: 1 | E12: FALSE | F12: =IF(E12,D12,0) -> 0
A13: チケット要件 | B13: T-A-04 外部 API 連携のモックテスト追加 | C13: テスト実行時に外部 API への実通信が発生せず、外部 API 依存テストをグループ指定で分離実行できる（例: #[Group('external')] + sail bin phpunit --exclude-group external で分離実行でき、通常実行では実通信が起きない） | D13: 1 | E13: FALSE | F13: =IF(E13,D13,0) -> 0
... A16: チケット要件 | B16: T-A-06 管理者ダッシュボード集計のキャッシュ化 | C16: 受講状態の遷移後にダッシュボードを開くと全体 KPI と資格別修了率がともに無効化され最新の集計値が表示される（古い件数・古い修了率が残らない） 確認方法（テスト）: 同梱 AdminDashboardCacheTest.php の test_admin_kpi_cache_is_invalidated_on_enrollment_status_change / test_completion_rate_cache_is_invalidated_on_enrollment_status_change（無効化未実装だと赤）が pass する | D16: 1 | E16: TRUE | F16: =IF(E16,D16,0) -> 1

Sheet 横断品質
A1: 大項目 | B1: 中項目 | C1: 評価基準 | D1: 評価点 | E1: 可否 | F1: 点数
A2: 横断品質 | B2: コード品質 | C2: プロジェクト一式が Laravel Pint で整形されている（sail bin pint --test を実行し「No fixable issues were found」と表示される） | D2: 3 | E2: TRUE | F2: =IF(E2,D2,0) -> 3
A3: 横断品質 | B3: コード品質 | C3: 追加・変更されたコードが既存の設計パターンに倣っている（Controller を薄く保ち業務ロジックを Action / Service へ切り出す / namespace は Controller=App\Http\Controllers・API=App\Http\Controllers\Api\V1・テスト=Tests\Feature\Http\... の規約に従う。確認は主に Controller） | D3: 8 | E3: FALSE | F3: =IF(E3,D3,0) -> 0
A4: 横断品質 | B4: コード品質 | C4: 追加・変更されたコードに明らかな規約逸脱がない（変数名に a / x 等の無意味な名前やローマ字を用いない / 不要な use・コメントアウトを残さない / DB 操作は Eloquent・バリデーションは FormRequest で統一） | D4: 5 | E4: FALSE | F4: =IF(E4,D4,0) -> 0
A5: 横断品質 | B5: コード品質 | C5: 追加された一覧・集計取得に N+1 の新規混入がない（Eager Loading〈with / withCount〉で回避）。客観担保＝パフォーマンス Task の同梱クエリ数テスト、加えて代表箇所（質問一覧 / ダッシュボード集計 / お知らせ履歴）を目視で確認（全 PR の精査は不要） | D5: 6 | E5: FALSE | F5: =IF(E5,D5,0) -> 0
A6: 横断品質 | B6: コード品質 | C6: （応用）追加・変更されたコードの型・ドキュメント作法が既存と同水準（引数・戻り値の型宣言 / declare(strict_types=1) / 主要メソッドの PHPDoc に処理内容を記述、引数・戻り値は型宣言で担保） | D6: 5 | E6: FALSE | F6: =IF(E6,D6,0) -> 0
A7: 横断品質 | B7: コード品質 | C7: （応用）外部 API キー・シークレット（Google / Gemini / Stripe）が .env で管理され、コードにハードコードされていない | D7: 4 | E7: TRUE | F7: =IF(E7,D7,0) -> 4
A8: 横断品質 | B8: テスト | C8: sail artisan test で全テストが pass する（同梱の赤テスト＝全 Bug・パフォーマンス Task を解消 + 既存テストを壊さない + 追加されたテストが緑） | D8: 10 | E8: TRUE | F8: =IF(E8,D8,0) -> 10
A9: 横断品質 | B9: テスト | C9: 追加されたテストがスモークでなく振る舞い（DB 反映 / 画面表示 / 認可 / 計算結果）を検証している | D9: 6 | E9: TRUE | F9: =IF(E9,D9,0) -> 6
A10: 横断品質 | B10: テスト | C10: （応用）追加実装分を含めてテストカバレッジが目標値（80% 以上）を満たす（Story 実装にテストを伴わせないと割り込む水準） | D10: 5 | E10: TRUE | F10: =IF(E10,D10,0) -> 5
A11: 横断品質 | B11: README | C11: README に外部 API 連携の .env 設定等、新規に必要な設定が追記され、その手順で環境構築できる | D11: 5 | E11: TRUE | F11: =IF(E11,D11,0) -> 5

Sheet 誤答リスト
A1: 中項目 | B1: 評価基準 | C1: 評価点
A2: =IFERROR(__xludf.DUMMYFUNCTION("IFERROR(QUERY({Story!A2:F232;Bug!A2:F232;Task!A2:F232;'横断品質'!A2:F232},""select Col2, Col3, Col4 where Col5 = false and Col2 is not null"",0),""（未達成の項目はありません）"")"),"S-B-01 質問掲示板") -> S-B-01 質問掲示板 | B2: =IFERROR(__xludf.DUMMYFUNCTION("""COMPUTED_VALUE"""),"【受講生】 1. 投稿者本人は回答 0 件のスレッドのみ削除でき、成功時にフラッシュメッセージ「質問を削除しました。」が表示される 2. 回答有りのスレッドは削除できず、フラッシュエラー「回答が付いているスレッドは削除できません。」が表示される") -> 【受講生】 1. 投稿者本人は回答 0 件のスレッドのみ削除でき、成功時にフラッシュメッセージ「質問を削除しました。」が表示される 2. 回答有りのスレッドは削除できず、フラッシュエラー「回答が付いているスレッドは削除できません。」が表示される | C2: =IFERROR(__xludf.DUMMYFUNCTION("""COMPUTED_VALUE"""),1.0) -> 1
A3: =IFERROR(__xludf.DUMMYFUNCTION("""COMPUTED_VALUE"""),"S-B-01 質問掲示板") -> S-B-01 質問掲示板 | B3: =IFERROR(__xludf.DUMMYFUNCTION("""COMPUTED_VALUE"""),"【受講生・コーチ】 1. 受講生は公開済資格すべて、コーチは担当資格のみのスレッドを一覧で見られる 2. 資格別 / 解決状態 / キーワード(タイトル / 本文 / 回答本文の OR 部分一致)で絞り込みできる 3. 質問スレッド作成(回答順ではない)の新着順 20 件 / ページのページネーションが実装されている") -> 【受講生・コーチ】 1. 受講生は公開済資格すべて、コーチは担当資格のみのスレッドを一覧で見られる 2. 資格別 / 解決状態 / キーワード(タイトル / 本文 / 回答本文の OR 部分一致)で絞り込みできる 3. 質問スレッド作成(回答順ではない)の新着順 20 件 / ページのページネーションが実装されている | C3: =IFERROR(__xludf.DUMMYFUNCTION("""COMPUTED_VALUE"""),2.0) -> 2
A4: =IFERROR(__xludf.DUMMYFUNCTION("""COMPUTED_VALUE"""),"S-B-01 質問掲示板") -> S-B-01 質問掲示板 | B4: =IFERROR(__xludf.DUMMYFUNCTION("""COMPUTED_VALUE"""),"【管理者】 1. /admin/qa-board 経由で全資格(公開停止資格含む)のスレッドを横断閲覧できる 2. 任意のスレッド / 回答を無条件で削除できる(スレッド削除時に配下回答も連動削除、フラッシュ「質問を削除しました。」) 3. 管理者の画面にはスレッド投稿 / 編集 / 解決マークの操作ボタンは表示されない(モデレーションは削除のみ)") -> 【管理者】 1. /admin/qa-board 経由で全資格(公開停止資格含む)のスレッドを横断閲覧できる 2. 任意のスレッド / 回答を無条件で削除できる(スレッド削除時に配下回答も連動削除、フラッシュ「質問を削除しました。」) 3. 管理者の画面にはスレッド投稿 / 編集 / 解決マークの操作ボタンは表示されない(モデレーションは削除のみ) | C4: =IFERROR(__xludf.DUMMYFUNCTION("""COMPUTED_VALUE"""),1.0) -> 1
A5: =IFERROR(__xludf.DUMMYFUNCTION("""COMPUTED_VALUE"""),"S-B-01 質問掲示板") -> S-B-01 質問掲示板 | B5: =IFERROR(__xludf.DUMMYFUNCTION("""COMPUTED_VALUE"""),"【コーチ・受講生】 1. コーチは担当外資格のスレッドを直接 URL 指定 or 一覧クエリで指定しても閲覧できない(資格存在は隠蔽しない) 2. 受講生・コーチは公開停止資格のスレッドを閲覧できない(資格自体が見えない扱い、管理者は引き続き閲覧可)") -> 【コーチ・受講生】 1. コーチは担当外資格のスレッドを直接 URL 指定 or 一覧クエリで指定しても閲覧できない(資格存在は隠蔽しない) 2. 受講生・コーチは公開停止資格のスレッドを閲覧できない(資格自体が見えない扱い、管理者は引き続き閲覧可) | C5: =IFERROR(__xludf.DUMMYFUNCTION("""COMPUTED_VALUE"""),2.0) -> 2
A6: =IFERROR(__xludf.DUMMYFUNCTION("""COMPUTED_VALUE"""),"S-B-01 質問掲示板") -> S-B-01 質問掲示板 | B6: =IFERROR(__xludf.DUMMYFUNCTION("""COMPUTED_VALUE"""),"【受講生・コーチ】 1. スレッド投稿 / 編集 / 回答投稿 / 回答編集フォームで違反時に日本語エラーが表示される a. 資格 = 必須(公開済資格のみ) b. タイトル = 必須・200 文字以内・全角通常空白のみ不可 c. 本文〈スレッド / 回答〉 = 必須・5000 文字以内・全角通常空白のみ不可 (メッセージ例: 「資格を選択してください。」「タイトルを入力してください。」「タイトルは 200 文字以内で入力してください。」「本文を入力してください。」「本文は 5000 文字以内で入力してく"&"ださい。」) ※文字数上限は blade の maxlength で入力段階から担保(超過入力不可のため超過時のエラー表示の確認は不要)") -> 【受講生・コーチ】 1. スレッド投稿 / 編集 / 回答投稿 / 回答編集フォームで違反時に日本語エラーが表示される a. 資格 = 必須(公開済資格のみ) b. タイトル = 必須・200 文字以内・全角通常空白のみ不可 c. 本文〈スレッド / 回答〉 = 必須・5000 文字以内・全角通常空白のみ不可 (メッセージ例: 「資格を選択してください。」「タイトルを入力してください。」「タイトルは 200 文字以内で入力してください。」「本文を入力してください。」「本文は 5000 文字以内で入力してください。」) ※文字数上限は blade の maxlength で入力段階から担保(超過入力不可のため超過時のエラー表示の確認は不要) | C6: =IFERROR(__xludf.DUMMYFUNCTION("""COMPUTED_VALUE"""),1.0) -> 1
A7: =IFERROR(__xludf.DUMMYFUNCTION("""COMPUTED_VALUE"""),"S-B-02 面談パックのマスタ管理") -> S-B-02 面談パックのマスタ管理 | B7: =IFERROR(__xludf.DUMMYFUNCTION("""COMPUTED_VALUE"""),"【管理者】 1. 面談パック管理画面で一覧を閲覧できる 2. パック名キーワード(部分一致)+ ステータス(下書き / 公開中 / アーカイブ)フィルタで絞り込める 3. 公開中を優先する並び順で表示される") -> 【管理者】 1. 面談パック管理画面で一覧を閲覧できる 2. パック名キーワード(部分一致)+ ステータス(下書き / 公開中 / アーカイブ)フィルタで絞り込める 3. 公開中を優先する並び順で表示される | C7: =IFERROR(__xludf.DUMMYFUNCTION("""COMPUTED_VALUE"""),1.0) -> 1
A8: =IFERROR(__xludf.DUMMYFUNCTION("""COMPUTED_VALUE"""),"S-B-02 面談パックのマスタ管理") -> S-B-02 面談パックのマスタ管理 | B8: =IFERROR(__xludf.DUMMYFUNCTION("""COMPUTED_VALUE"""),"【管理者】 1. 新規作成すると下書き状態で作成される 2. 作成された面談パックの詳細画面へリダイレクトし、フラッシュメッセージ「面談パックを作成しました。」が表示される") -> 【管理者】 1. 新規作成すると下書き状態で作成される 2. 作成された面談パックの詳細画面へリダイレクトし、フラッシュメッセージ「面談パックを作成しました。」が表示される | C8: =IFERROR(__xludf.DUMMYFUNCTION("""COMPUTED_VALUE"""),1.0) -> 1
A9: =IFERROR(__xludf.DUMMYFUNCTION("""COMPUTED_VALUE"""),"S-B-02 面談パックのマスタ管理") -> S-B-02 面談パックのマスタ管理 | B9: =IFERROR(__xludf.DUMMYFUNCTION("""COMPUTED_VALUE"""),"【管理者】 1. 公開(下書き → 公開中)/ アーカイブ(公開中 → アーカイブ)/ 下書きへ戻す(アーカイブ → 下書き)の 3 操作がそれぞれ遷移元の状態でのみ実行できる 2. 成功時に詳細画面へリダイレクトし、フラッシュ表示(下書き→公開「面談パックを公開しました。」/ 公開中→アーカイブ「面談パックをアーカイブしました。」/ アーカイブ→下書き「面談パックを下書きへ戻しました。」)") -> 【管理者】 1. 公開(下書き → 公開中)/ アーカイブ(公開中 → アーカイブ)/ 下書きへ戻す(アーカイブ → 下書き)の 3 操作がそれぞれ遷移元の状態でのみ実行できる 2. 成功時に詳細画面へリダイレクトし、フラッシュ表示(下書き→公開「面談パックを公開しました。」/ 公開中→アーカイブ「面談パックをアーカイブしました。」/ アーカイブ→下書き「面談パックを下書きへ戻しました。」) | C9: =IFERROR(__xludf.DUMMYFUNCTION("""COMPUTED_VALUE"""),1.0) -> 1
A10: =IFERROR(__xludf.DUMMYFUNCTION("""COMPUTED_VALUE"""),"S-B-02 面談パックのマスタ管理") -> S-B-02 面談パックのマスタ管理 | B10: =IFERROR(__xludf.DUMMYFUNCTION("""COMPUTED_VALUE"""),"【管理者】 1. 違反時に日本語エラーが表示される a. パック名 = 必須・100 文字以内 b. 説明 = 任意・2000 文字以内 c. 面談回数 = 必須・1〜100 の整数 d. 価格 = 必須・0〜1,000,000 円の整数 e. Stripe 価格 ID = 任意・255 文字以内 f. 並び順 = 任意・0 以上の整数 (メッセージ例: 「SKU 名 を入力してください。」「面談回数 は 1 以上の値を指定してください。」「価格(円) は 1000000 以下の値を指定してください。」)") -> 【管理者】 1. 違反時に日本語エラーが表示される a. パック名 = 必須・100 文字以内 b. 説明 = 任意・2000 文字以内 c. 面談回数 = 必須・1〜100 の整数 d. 価格 = 必須・0〜1,000,000 円の整数 e. Stripe 価格 ID = 任意・255 文字以内 f. 並び順 = 任意・0 以上の整数 (メッセージ例: 「SKU 名 を入力してください。」「面談回数 は 1 以上の値を指定してください。」「価格(円) は 1000000 以下の値を指定してください。」) | C10: =IFERROR(__xludf.DUMMYFUNCTION("""COMPUTED_VALUE"""),1.0) -> 1
A11: =IFERROR(__xludf.DUMMYFUNCTION("""COMPUTED_VALUE"""),"S-B-03 プランのマスタ管理") -> S-B-03 プランのマスタ管理 | B11: =IFERROR(__xludf.DUMMYFUNCTION("""COMPUTED_VALUE"""),"【管理者】 1. プラン管理の一覧を開くと、プラン名キーワード(部分一致)とステータス(下書き / 公開中 / アーカイブ)で絞り込みできる 2. 各行に契約中の受講者数が表示される 3. 公開中を優先する並び順で表示される") -> 【管理者】 1. プラン管理の一覧を開くと、プラン名キーワード(部分一致)とステータス(下書き / 公開中 / アーカイブ)で絞り込みできる 2. 各行に契約中の受講者数が表示される 3. 公開中を優先する並び順で表示される | C11: =IFERROR(__xludf.DUMMYFUNCTION("""COMPUTED_VALUE"""),1.0) -> 1
A12: =IFERROR(__xludf.DUMMYFUNCTION("""COMPUTED_VALUE"""),"S-B-03 プランのマスタ管理") -> S-B-03 プランのマスタ管理 | B12: =IFERROR(__xludf.DUMMYFUNCTION("""COMPUTED_VALUE"""),"【管理者】 1. 新規作成すると下書き状態でプランが作成される 2. 作成したプランの詳細画面へリダイレクトし、フラッシュメッセージ「プランを作成しました。」が表示される") -> 【管理者】 1. 新規作成すると下書き状態でプランが作成される 2. 作成したプランの詳細画面へリダイレクトし、フラッシュメッセージ「プランを作成しました。」が表示される | C12: =IFERROR(__xludf.DUMMYFUNCTION("""COMPUTED_VALUE"""),1.0) -> 1
A13: =IFERROR(__xludf.DUMMYFUNCTION("""COMPUTED_VALUE"""),"S-B-03 プランのマスタ管理") -> S-B-03 プランのマスタ管理 | B13: =IFERROR(__xludf.DUMMYFUNCTION("""COMPUTED_VALUE"""),"【管理者】 1. 公開中 / アーカイブ状態のプラン、または下書きでも受講者が 1 名以上紐づくプランは削除できず、元画面に戻ってフラッシュエラーが表示される(公開中 / アーカイブ「下書き状態のプランのみ削除できます。先に下書きに戻すか、アーカイブを利用してください。」/ 受講者紐付き「このプランは受講者が紐づいているため削除できません。」)") -> 【管理者】 1. 公開中 / アーカイブ状態のプラン、または下書きでも受講者が 1 名以上紐づくプランは削除できず、元画面に戻ってフラッシュエラーが表示される(公開中 / アーカイブ「下書き状態のプランのみ削除できます。先に下書きに戻すか、アーカイブを利用してください。」/ 受講者紐付き「このプランは受講者が紐づいているため削除できません。」) | C13: =IFERROR(__xludf.DUMMYFUNCTION("""COMPUTED_VALUE"""),1.0) -> 1
A14: =IFERROR(__xludf.DUMMYFUNCTION("""COMPUTED_VALUE"""),"S-B-03 プランのマスタ管理") -> S-B-03 プランのマスタ管理 | B14: =IFERROR(__xludf.DUMMYFUNCTION("""COMPUTED_VALUE"""),"【管理者】 1. 公開(下書き → 公開中)/ アーカイブ(公開中 → アーカイブ)/ 下書きへ戻す(アーカイブ → 下書き)を正しい遷移元状態から実行すると状態が遷移する 2. 詳細画面へリダイレクトし、フラッシュ表示(下書き→公開「プランを公開しました。」/ 公開中→アーカイブ「プランをアーカイブしました。」/ アーカイブ→下書き「プランを下書きへ戻しました。」)") -> 【管理者】 1. 公開(下書き → 公開中)/ アーカイブ(公開中 → アーカイブ)/ 下書きへ戻す(アーカイブ → 下書き)を正しい遷移元状態から実行すると状態が遷移する 2. 詳細画面へリダイレクトし、フラッシュ表示(下書き→公開「プランを公開しました。」/ 公開中→アーカイブ「プランをアーカイブしました。」/ アーカイブ→下書き「プランを下書きへ戻しました。」) | C14: =IFERROR(__xludf.DUMMYFUNCTION("""COMPUTED_VALUE"""),1.0) -> 1
A15: =IFERROR(__xludf.DUMMYFUNCTION("""COMPUTED_VALUE"""),"S-B-03 プランのマスタ管理") -> S-B-03 プランのマスタ管理 | B15: =IFERROR(__xludf.DUMMYFUNCTION("""COMPUTED_VALUE"""),"【管理者】 1. 違反時に日本語エラーが表示される a. プラン名 = 必須・100 文字以内 b. 説明 = 任意・2000 文字以内 c. 受講期間〈日〉 = 必須・1〜3650 の整数 d. 初期付与面談回数 = 必須・0〜1000 の整数 e. 並び順 = 任意・0 以上の整数 (メッセージ例: 「プラン名 を入力してください。」「受講期間(日) は 3650 以下の値を指定してください。」)") -> 【管理者】 1. 違反時に日本語エラーが表示される a. プラン名 = 必須・100 文字以内 b. 説明 = 任意・2000 文字以内 c. 受講期間〈日〉 = 必須・1〜3650 の整数 d. 初期付与面談回数 = 必須・0〜1000 の整数 e. 並び順 = 任意・0 以上の整数 (メッセージ例: 「プラン名 を入力してください。」「受講期間(日) は 3650 以下の値を指定してください。」) | C15: =IFERROR(__xludf.DUMMYFUNCTION("""COMPUTED_VALUE"""),1.0) -> 1
A16: =IFERROR(__xludf.DUMMYFUNCTION("""COMPUTED_VALUE"""),"S-B-04 通知基盤（アプリ内＋メール）") -> S-B-04 通知基盤（アプリ内＋メール） | B16: =IFERROR(__xludf.DUMMYFUNCTION("""COMPUTED_VALUE"""),"【受講生・コーチ】 1. 通知行クリックで未読通知が既読化される 2. 通知種別に応じた業務画面(chat ルーム / Q&A スレッド / 面談一覧)へリダイレクトされる") -> 【受講生・コーチ】 1. 通知行クリックで未読通知が既読化される 2. 通知種別に応じた業務画面(chat ルーム / Q&A スレッド / 面談一覧)へリダイレクトされる | C16: =IFERROR(__xludf.DUMMYFUNCTION("""COMPUTED_VALUE"""),1.0) -> 1
A17: =IFERROR(__xludf.DUMMYFUNCTION("""COMPUTED_VALUE"""),"S-B-04 通知基盤（アプリ内＋メール）") -> S-B-04 通知基盤（アプリ内＋メール） | B17: =IFERROR(__xludf.DUMMYFUNCTION("""COMPUTED_VALUE"""),"【受講生・コーチ】 1. chat ルームで新規メッセージが投稿された際に、送信者を除くルームメンバーの通知一覧に通知が表示され、対象者にメールも届く(送信者本人には表示・送信されない)") -> 【受講生・コーチ】 1. chat ルームで新規メッセージが投稿された際に、送信者を除くルームメンバーの通知一覧に通知が表示され、対象者にメールも届く(送信者本人には表示・送信されない) | C17: =IFERROR(__xludf.DUMMYFUNCTION("""COMPUTED_VALUE"""),1.0) -> 1
A18: =IFERROR(__xludf.DUMMYFUNCTION("""COMPUTED_VALUE"""),"S-B-04 通知基盤（アプリ内＋メール）") -> S-B-04 通知基盤（アプリ内＋メール） | B18: =IFERROR(__xludf.DUMMYFUNCTION("""COMPUTED_VALUE"""),"【受講生・コーチ】 1. Q&A スレッドに新規回答が投稿された際にスレッド投稿者の通知一覧に通知が表示され、メールも届く(回答者 = スレッド投稿者の自己回答時は表示・送信されない)") -> 【受講生・コーチ】 1. Q&A スレッドに新規回答が投稿された際にスレッド投稿者の通知一覧に通知が表示され、メールも届く(回答者 = スレッド投稿者の自己回答時は表示・送信されない) | C18: =IFERROR(__xludf.DUMMYFUNCTION("""COMPUTED_VALUE"""),1.0) -> 1
A19: =IFERROR(__xludf.DUMMYFUNCTION("""COMPUTED_VALUE"""),"S-B-04 通知基盤（アプリ内＋メール）") -> S-B-04 通知基盤（アプリ内＋メール） | B19: =IFERROR(__xludf.DUMMYFUNCTION("""COMPUTED_VALUE"""),"【受講生・コーチ】 1. 受講生が面談を予約した際に担当コーチの通知一覧に通知が表示され、メールも届き、受講生本人には表示・送信されない") -> 【受講生・コーチ】 1. 受講生が面談を予約した際に担当コーチの通知一覧に通知が表示され、メールも届き、受講生本人には表示・送信されない | C19: =IFERROR(__xludf.DUMMYFUNCTION("""COMPUTED_VALUE"""),1.0) -> 1
A20: =IFERROR(__xludf.DUMMYFUNCTION("""COMPUTED_VALUE"""),"S-B-04 通知基盤（アプリ内＋メール）") -> S-B-04 通知基盤（アプリ内＋メール） | B20: =IFERROR(__xludf.DUMMYFUNCTION("""COMPUTED_VALUE"""),"【受講生・コーチ】 1. 当事者(受講生 or 担当コーチ)が予約済面談をキャンセルした際に相手方の通知一覧に通知が表示され、メールも届き、自身には表示・送信されない") -> 【受講生・コーチ】 1. 当事者(受講生 or 担当コーチ)が予約済面談をキャンセルした際に相手方の通知一覧に通知が表示され、メールも届き、自身には表示・送信されない | C20: =IFERROR(__xludf.DUMMYFUNCTION("""COMPUTED_VALUE"""),1.0) -> 1
A21: =IFERROR(__xludf.DUMMYFUNCTION("""COMPUTED_VALUE"""),"S-B-04 通知基盤（アプリ内＋メール）") -> S-B-04 通知基盤（アプリ内＋メール） | B21: =IFERROR(__xludf.DUMMYFUNCTION("""COMPUTED_VALUE"""),"【管理者】 1. 管理者は本 4 種いずれの通知も受信しない(通知一覧に表示されない)") -> 【管理者】 1. 管理者は本 4 種いずれの通知も受信しない(通知一覧に表示されない) | C21: =IFERROR(__xludf.DUMMYFUNCTION("""COMPUTED_VALUE"""),1.0) -> 1
A22: =IFERROR(__xludf.DUMMYFUNCTION("""COMPUTED_VALUE"""),"S-B-05 個人学習目標の管理") -> S-B-05 個人学習目標の管理 | B22: =IFERROR(__xludf.DUMMYFUNCTION("""COMPUTED_VALUE"""),"【受講生】 1. 自分の受講登録詳細画面で目標追加フォームを送信すると、その受講登録詳細画面へリダイレクトする 2. 未達成状態(達成日時なし)で目標が作成され、フラッシュメッセージ「目標を追加しました。」が表示される") -> 【受講生】 1. 自分の受講登録詳細画面で目標追加フォームを送信すると、その受講登録詳細画面へリダイレクトする 2. 未達成状態(達成日時なし)で目標が作成され、フラッシュメッセージ「目標を追加しました。」が表示される | C22: =IFERROR(__xludf.DUMMYFUNCTION("""COMPUTED_VALUE"""),1.0) -> 1
A23: =IFERROR(__xludf.DUMMYFUNCTION("""COMPUTED_VALUE"""),"S-B-05 個人学習目標の管理") -> S-B-05 個人学習目標の管理 | B23: =IFERROR(__xludf.DUMMYFUNCTION("""COMPUTED_VALUE"""),"【受講生】 1. 本人が目標編集リンクから「目標を編集」ページに遷移して目標 / 目標期日 / 詳細 を更新できる 2. 編集では達成 / 未達成の状態は変わらない 3. 成功時に受講登録詳細画面へリダイレクトし、フラッシュメッセージ「目標を更新しました。」が表示される") -> 【受講生】 1. 本人が目標編集リンクから「目標を編集」ページに遷移して目標 / 目標期日 / 詳細 を更新できる 2. 編集では達成 / 未達成の状態は変わらない 3. 成功時に受講登録詳細画面へリダイレクトし、フラッシュメッセージ「目標を更新しました。」が表示される | C23: =IFERROR(__xludf.DUMMYFUNCTION("""COMPUTED_VALUE"""),1.0) -> 1
A24: =IFERROR(__xludf.DUMMYFUNCTION("""COMPUTED_VALUE"""),"S-B-05 個人学習目標の管理") -> S-B-05 個人学習目標の管理 | B24: =IFERROR(__xludf.DUMMYFUNCTION("""COMPUTED_VALUE"""),"【受講生】 1. 本人が目標を削除すると受講登録詳細画面へリダイレクトし、フラッシュメッセージ「目標を削除しました。」が表示される") -> 【受講生】 1. 本人が目標を削除すると受講登録詳細画面へリダイレクトし、フラッシュメッセージ「目標を削除しました。」が表示される | C24: =IFERROR(__xludf.DUMMYFUNCTION("""COMPUTED_VALUE"""),1.0) -> 1
A25: =IFERROR(__xludf.DUMMYFUNCTION("""COMPUTED_VALUE"""),"S-B-05 個人学習目標の管理") -> S-B-05 個人学習目標の管理 | B25: =IFERROR(__xludf.DUMMYFUNCTION("""COMPUTED_VALUE"""),"【受講生】 1. 本人が達成マーク / 達成解除で目標の達成状態をトグルでき、一覧の達成済 / 未達成の表示が切り替わる 2. いずれも成功時に受講登録詳細画面へリダイレクトし、フラッシュ表示(「目標を達成済にしました。」「目標を未達成に戻しました。」)") -> 【受講生】 1. 本人が達成マーク / 達成解除で目標の達成状態をトグルでき、一覧の達成済 / 未達成の表示が切り替わる 2. いずれも成功時に受講登録詳細画面へリダイレクトし、フラッシュ表示(「目標を達成済にしました。」「目標を未達成に戻しました。」) | C25: =IFERROR(__xludf.DUMMYFUNCTION("""COMPUTED_VALUE"""),1.0) -> 1
A26: =IFERROR(__xludf.DUMMYFUNCTION("""COMPUTED_VALUE"""),"S-B-05 個人学習目標の管理") -> S-B-05 個人学習目標の管理 | B26: =IFERROR(__xludf.DUMMYFUNCTION("""COMPUTED_VALUE"""),"【受講生・コーチ・管理者】 1. 受講生本人の受講登録詳細画面で自分の目標が未達成優先(達成済は末尾) → 目標期日が近い順 で一覧表示される 2. 未達成 / 達成済 の視覚的区別が付く 3. コーチ / 管理者の閲覧時は一覧は見えるが CRUD / 達成マーク操作ボタンは表示されない") -> 【受講生・コーチ・管理者】 1. 受講生本人の受講登録詳細画面で自分の目標が未達成優先(達成済は末尾) → 目標期日が近い順 で一覧表示される 2. 未達成 / 達成済 の視覚的区別が付く 3. コーチ / 管理者の閲覧時は一覧は見えるが CRUD / 達成マーク操作ボタンは表示されない | C26: =IFERROR(__xludf.DUMMYFUNCTION("""COMPUTED_VALUE"""),1.0) -> 1
A27: =IFERROR(__xludf.DUMMYFUNCTION("""COMPUTED_VALUE"""),"S-B-05 個人学習目標の管理") -> S-B-05 個人学習目標の管理 | B27: =IFERROR(__xludf.DUMMYFUNCTION("""COMPUTED_VALUE"""),"【受講生・コーチ・管理者】 1. 他受講生は他人の受講登録詳細画面にアクセスできず目標一覧にも到達できない 2. コーチ / 管理者は目標の編集専用ページにアクセスできない(操作ボタンの非表示と合わせ、本人以外に目標を操作する経路がない)") -> 【受講生・コーチ・管理者】 1. 他受講生は他人の受講登録詳細画面にアクセスできず目標一覧にも到達できない 2. コーチ / 管理者は目標の編集専用ページにアクセスできない(操作ボタンの非表示と合わせ、本人以外に目標を操作する経路がない) | C27: =IFERROR(__xludf.DUMMYFUNCTION("""COMPUTED_VALUE"""),1.0) -> 1
A28: =IFERROR(__xludf.DUMMYFUNCTION("""COMPUTED_VALUE"""),"S-B-05 個人学習目標の管理") -> S-B-05 個人学習目標の管理 | B28: =IFERROR(__xludf.DUMMYFUNCTION("""COMPUTED_VALUE"""),"【受講生】 1. 違反時に日本語エラーが表示される a. タイトル = 必須・100 文字以内 b. 詳細 = 任意・1000 文字以内 c. 目標期日 = 任意・日付形式 (メッセージ例: 「目標 を入力してください。」「目標 は 100 文字以内で入力してください。」「目標期日 は有効な日付ではありません。」)") -> 【受講生】 1. 違反時に日本語エラーが表示される a. タイトル = 必須・100 文字以内 b. 詳細 = 任意・1000 文字以内 c. 目標期日 = 任意・日付形式 (メッセージ例: 「目標 を入力してください。」「目標 は 100 文字以内で入力してください。」「目標期日 は有効な日付ではありません。」) | C28: =IFERROR(__xludf.DUMMYFUNCTION("""COMPUTED_VALUE"""),1.0) -> 1
A29: =IFERROR(__xludf.DUMMYFUNCTION("""COMPUTED_VALUE"""),"S-B-06 設定・プロフィール") -> S-B-06 設定・プロフィール | B29: =IFERROR(__xludf.DUMMYFUNCTION("""COMPUTED_VALUE"""),"【受講生・コーチ・管理者】 1. 氏名・自己紹介を更新成功すると、プロフィールタブへリダイレクトし成功メッセージ「プロフィールを更新しました。」が表示される 2. メール欄は読み取り専用で表示され画面から編集できない") -> 【受講生・コーチ・管理者】 1. 氏名・自己紹介を更新成功すると、プロフィールタブへリダイレクトし成功メッセージ「プロフィールを更新しました。」が表示される 2. メール欄は読み取り専用で表示され画面から編集できない | C29: =IFERROR(__xludf.DUMMYFUNCTION("""COMPUTED_VALUE"""),1.0) -> 1
A30: =IFERROR(__xludf.DUMMYFUNCTION("""COMPUTED_VALUE"""),"S-B-06 設定・プロフィール") -> S-B-06 設定・プロフィール | B30: =IFERROR(__xludf.DUMMYFUNCTION("""COMPUTED_VALUE"""),"【コーチ・受講生・管理者】 1. コーチが編集フォームを開くと固定面談 URL 入力欄が表示され更新できる(空入力で値がクリアされる) 2. 受講生 / 管理者のプロフィール編集には固定面談 URL 入力欄が表示されない") -> 【コーチ・受講生・管理者】 1. コーチが編集フォームを開くと固定面談 URL 入力欄が表示され更新できる(空入力で値がクリアされる) 2. 受講生 / 管理者のプロフィール編集には固定面談 URL 入力欄が表示されない | C30: =IFERROR(__xludf.DUMMYFUNCTION("""COMPUTED_VALUE"""),1.0) -> 1
A31: =IFERROR(__xludf.DUMMYFUNCTION("""COMPUTED_VALUE"""),"S-B-06 設定・プロフィール") -> S-B-06 設定・プロフィール | B31: =IFERROR(__xludf.DUMMYFUNCTION("""COMPUTED_VALUE"""),"【受講生・コーチ・管理者】 1. 違反時に該当タブで日本語エラーが表示され入力値も復元される a. 氏名 = 必須・50 文字以内 b. 自己紹介 = 任意・1000 文字以内 c. 固定面談 URL〈コーチのみ〉 = URL 形式・500 文字以内 (メッセージ例: 「氏名 を入力してください。」「氏名 は 50 文字以内で入力してください。」「固定面談 URL の形式が正しくありません。」)") -> 【受講生・コーチ・管理者】 1. 違反時に該当タブで日本語エラーが表示され入力値も復元される a. 氏名 = 必須・50 文字以内 b. 自己紹介 = 任意・1000 文字以内 c. 固定面談 URL〈コーチのみ〉 = URL 形式・500 文字以内 (メッセージ例: 「氏名 を入力してください。」「氏名 は 50 文字以内で入力してください。」「固定面談 URL の形式が正しくありません。」) | C31: =IFERROR(__xludf.DUMMYFUNCTION("""COMPUTED_VALUE"""),1.0) -> 1
A32: =IFERROR(__xludf.DUMMYFUNCTION("""COMPUTED_VALUE"""),"S-B-07 受講生メモの管理（コーチ）") -> S-B-07 受講生メモの管理（コーチ） | B32: =IFERROR(__xludf.DUMMYFUNCTION("""COMPUTED_VALUE"""),"【コーチ・管理者】 1. 担当資格に登録した受講生の受講登録に対してコーチ(または管理者)がメモを追加すると保存され、元の受講登録詳細画面に戻ってフラッシュメッセージ「メモを追加しました。」が表示される 2. 作成者には操作したコーチ / 管理者が記録される") -> 【コーチ・管理者】 1. 担当資格に登録した受講生の受講登録に対してコーチ(または管理者)がメモを追加すると保存され、元の受講登録詳細画面に戻ってフラッシュメッセージ「メモを追加しました。」が表示される 2. 作成者には操作したコーチ / 管理者が記録される | C32: =IFERROR(__xludf.DUMMYFUNCTION("""COMPUTED_VALUE"""),1.0) -> 1
A33: =IFERROR(__xludf.DUMMYFUNCTION("""COMPUTED_VALUE"""),"S-B-07 受講生メモの管理（コーチ）") -> S-B-07 受講生メモの管理（コーチ） | B33: =IFERROR(__xludf.DUMMYFUNCTION("""COMPUTED_VALUE"""),"【コーチ・管理者】 1. 自分が作成したメモ(管理者は全メモ)を専用編集ページで本文更新できる 2. 成功時に作成者は変わらず元の画面に戻ってフラッシュメッセージ「メモを更新しました。」が表示される") -> 【コーチ・管理者】 1. 自分が作成したメモ(管理者は全メモ)を専用編集ページで本文更新できる 2. 成功時に作成者は変わらず元の画面に戻ってフラッシュメッセージ「メモを更新しました。」が表示される | C33: =IFERROR(__xludf.DUMMYFUNCTION("""COMPUTED_VALUE"""),1.0) -> 1
A34: =IFERROR(__xludf.DUMMYFUNCTION("""COMPUTED_VALUE"""),"S-B-07 受講生メモの管理（コーチ）") -> S-B-07 受講生メモの管理（コーチ） | B34: =IFERROR(__xludf.DUMMYFUNCTION("""COMPUTED_VALUE"""),"【コーチ・管理者】 1. 自分が作成したメモ(管理者は全メモ)を削除でき、成功時に元の画面に戻ってフラッシュメッセージ「メモを削除しました。」が表示される") -> 【コーチ・管理者】 1. 自分が作成したメモ(管理者は全メモ)を削除でき、成功時に元の画面に戻ってフラッシュメッセージ「メモを削除しました。」が表示される | C34: =IFERROR(__xludf.DUMMYFUNCTION("""COMPUTED_VALUE"""),1.0) -> 1
A35: =IFERROR(__xludf.DUMMYFUNCTION("""COMPUTED_VALUE"""),"S-B-07 受講生メモの管理（コーチ）") -> S-B-07 受講生メモの管理（コーチ） | B35: =IFERROR(__xludf.DUMMYFUNCTION("""COMPUTED_VALUE"""),"【コーチ・管理者】 1. 担当資格に登録した受講生の受講登録詳細画面でメモが時系列降順で表示される 2. 自分が作成したメモにのみ編集 / 削除ボタンが出る(他コーチのメモは閲覧のみ)。管理者は全メモに編集 / 削除ボタンが表示される") -> 【コーチ・管理者】 1. 担当資格に登録した受講生の受講登録詳細画面でメモが時系列降順で表示される 2. 自分が作成したメモにのみ編集 / 削除ボタンが出る(他コーチのメモは閲覧のみ)。管理者は全メモに編集 / 削除ボタンが表示される | C35: =IFERROR(__xludf.DUMMYFUNCTION("""COMPUTED_VALUE"""),1.0) -> 1
A36: =IFERROR(__xludf.DUMMYFUNCTION("""COMPUTED_VALUE"""),"S-B-07 受講生メモの管理（コーチ）") -> S-B-07 受講生メモの管理（コーチ） | B36: =IFERROR(__xludf.DUMMYFUNCTION("""COMPUTED_VALUE"""),"【受講生】 1. 受講生が自分の受講登録詳細画面を開いてもメモのセクション自体が表示されず、メモ系ルートにもアクセスできない") -> 【受講生】 1. 受講生が自分の受講登録詳細画面を開いてもメモのセクション自体が表示されず、メモ系ルートにもアクセスできない | C36: =IFERROR(__xludf.DUMMYFUNCTION("""COMPUTED_VALUE"""),1.0) -> 1
A37: =IFERROR(__xludf.DUMMYFUNCTION("""COMPUTED_VALUE"""),"S-B-07 受講生メモの管理（コーチ）") -> S-B-07 受講生メモの管理（コーチ） | B37: =IFERROR(__xludf.DUMMYFUNCTION("""COMPUTED_VALUE"""),"【コーチ】 1. コーチは担当していない資格の受講登録詳細にアクセスできずメモにも到達できない 2. 他コーチが作成したメモの編集専用ページにもアクセスできない") -> 【コーチ】 1. コーチは担当していない資格の受講登録詳細にアクセスできずメモにも到達できない 2. 他コーチが作成したメモの編集専用ページにもアクセスできない | C37: =IFERROR(__xludf.DUMMYFUNCTION("""COMPUTED_VALUE"""),1.0) -> 1
A38: =IFERROR(__xludf.DUMMYFUNCTION("""COMPUTED_VALUE"""),"S-B-07 受講生メモの管理（コーチ）") -> S-B-07 受講生メモの管理（コーチ） | B38: =IFERROR(__xludf.DUMMYFUNCTION("""COMPUTED_VALUE"""),"【コーチ・管理者】 1. 違反時に入力値の再表示とともに日本語エラーが表示される(本文 = 必須・2000 文字以内) (メッセージ例: 「メモ本文 を入力してください。」「メモ本文 は 2000 文字以内で入力してください。」)") -> 【コーチ・管理者】 1. 違反時に入力値の再表示とともに日本語エラーが表示される(本文 = 必須・2000 文字以内) (メッセージ例: 「メモ本文 を入力してください。」「メモ本文 は 2000 文字以内で入力してください。」) | C38: =IFERROR(__xludf.DUMMYFUNCTION("""COMPUTED_VALUE"""),1.0) -> 1
A39: =IFERROR(__xludf.DUMMYFUNCTION("""COMPUTED_VALUE"""),"S-B-08 お知らせ配信（管理者）") -> S-B-08 お知らせ配信（管理者） | B39: =IFERROR(__xludf.DUMMYFUNCTION("""COMPUTED_VALUE"""),"【管理者】 1. 受講中でない受講生(退会済 / 修了済 / 招待中)/ コーチ / 管理者 は配信対象集合から除外され、配信件数にも含まれない") -> 【管理者】 1. 受講中でない受講生(退会済 / 修了済 / 招待中)/ コーチ / 管理者 は配信対象集合から除外され、配信件数にも含まれない | C39: =IFERROR(__xludf.DUMMYFUNCTION("""COMPUTED_VALUE"""),1.0) -> 1
A40: =IFERROR(__xludf.DUMMYFUNCTION("""COMPUTED_VALUE"""),"S-B-08 お知らせ配信（管理者）") -> S-B-08 お知らせ配信（管理者） | B40: =IFERROR(__xludf.DUMMYFUNCTION("""COMPUTED_VALUE"""),"【管理者】 1. 配信作成でバリデーションが行われ、違反時に日本語エラーが表示され配信は実行されない a. タイトル = 必須・200 文字以内 b. 本文 = 必須・5000 文字以内 c. 配信対象タイプ = 必須・全受講生 / 資格指定 / ユーザー指定のいずれか d. 配信先資格 = 資格指定時のみ必須・既存資格と整合〈他タイプでは指定不可〉 e. 配信先ユーザー = ユーザー指定時のみ必須・既存受講生と整合〈他タイプでは指定不可〉 (メッセージ例: 「タイトルを入力してください。」「本文を入力し"&"てください。」「配信対象タイプが『資格指定』のとき、配信対象の資格を選択してください。」「配信対象タイプが『ユーザー指定』のとき、配信対象のユーザーを選択してください。」)") -> 【管理者】 1. 配信作成でバリデーションが行われ、違反時に日本語エラーが表示され配信は実行されない a. タイトル = 必須・200 文字以内 b. 本文 = 必須・5000 文字以内 c. 配信対象タイプ = 必須・全受講生 / 資格指定 / ユーザー指定のいずれか d. 配信先資格 = 資格指定時のみ必須・既存資格と整合〈他タイプでは指定不可〉 e. 配信先ユーザー = ユーザー指定時のみ必須・既存受講生と整合〈他タイプでは指定不可〉 (メッセージ例: 「タイトルを入力してください。」「本文を入力してください。」「配信対象タイプが『資格指定』のとき、配信対象の資格を選択してください。」「配信対象タイプが『ユーザー指定』のとき、配信対象のユーザーを選択してください。」) | C40: =IFERROR(__xludf.DUMMYFUNCTION("""COMPUTED_VALUE"""),1.0) -> 1
...
